<?xml version="1.0" encoding="utf-8"?>
<!-- This URDF was automatically created by SolidWorks to URDF Exporter! Originally created by Stephen Brawner (brawner@gmail.com) 
     Commit Version: 1.6.0-1-g15f4949  Build Version: 1.6.7594.29634
     For more information, please see http://wiki.ros.org/sw_urdf_exporter -->
<robot
  name="robot_final_urdf">
  <link
    name="base_link">
    <inertial>
      <origin
        xyz="-0.433405300680736 -0.847260680178481 0.336290838038208"
        rpy="0 0 0" />
      <mass
        value="97.6494336758734" />
      <inertia
        ixx="4.23300603058599"
        ixy="-1.31803217147692E-30"
        ixz="-1.35416949214728E-31"
        iyy="4.23300603058599"
        iyz="4.22232909632054E-17"
        izz="7.83611037734186" />
    </inertial>
    <visual>
      <origin
        xyz="0 0 0"
        rpy="0 0 0" />
      <geometry>
        <mesh
          filename="package://robot_final_urdf/meshes/base_link.STL" />
      </geometry>
      <material
        name="">
        <color
          rgba="0.627450980392157 0.627450980392157 0.627450980392157 1" />
      </material>
    </visual>
    <collision>
      <origin
        xyz="0 0 0"
        rpy="0 0 0" />
      <geometry>
        <mesh
          filename="package://robot_final_urdf/meshes/base_link.STL" />
      </geometry>
    </collision>
  </link>
  <link
    name="1_Link">
    <inertial>
      <origin
        xyz="-0.0905262838277687 0.341511094747869 -0.0260552507766272"
        rpy="0 0 0" />
      <mass
        value="78.7488935718911" />
      <inertia
        ixx="4.06250740278684"
        ixy="-2.13142266896941E-17"
        ixz="0"
        iyy="1.53685696330927"
        iyz="6.42522970364867E-16"
        izz="3.75052034482715" />
    </inertial>
    <visual>
      <origin
        xyz="0 0 0"
        rpy="0 0 0" />
      <geometry>
        <mesh
          filename="package://robot_final_urdf/meshes/1_Link.STL" />
      </geometry>
      <material
        name="">
        <color
          rgba="0.627450980392157 0.627450980392157 0.627450980392157 1" />
      </material>
    </visual>
    <collision>
      <origin
        xyz="0 0 0"
        rpy="0 0 0" />
      <geometry>
        <mesh
          filename="package://robot_final_urdf/meshes/1_Link.STL" />
      </geometry>
    </collision>
  </link>
  <joint
    name="j_1"
    type="revolute">
    <origin
      xyz="-0.43341 -0.38869 -0.84726"
      rpy="3.1416 0.63343 0" />
    <parent
      link="base_link" />
    <child
      link="1_Link" />
    <axis
      xyz="0 1 0" />
    <limit
      lower="-3.14"
      upper="3.14"
      effort="0"
      velocity="0" />
  </joint>
  <link
    name="2_Link">
    <inertial>
      <origin
        xyz="4.88498130835069E-15 -0.395 -8.43769498715119E-15"
        rpy="0 0 0" />
      <mass
        value="45.3561944901924" />
      <inertia
        ixx="3.0299018748189"
        ixy="1.06997743998249E-14"
        ixz="1.33493881605676E-16"
        iyy="0.40849637933104"
        iyz="-1.18603079060113E-14"
        izz="2.9287706762524" />
    </inertial>
    <visual>
      <origin
        xyz="0 0 0"
        rpy="0 0 0" />
      <geometry>
        <mesh
          filename="package://robot_final_urdf/meshes/2_Link.STL" />
      </geometry>
      <material
        name="">
        <color
          rgba="0.627450980392157 0.627450980392157 0.627450980392157 1" />
      </material>
    </visual>
    <collision>
      <origin
        xyz="0 0 0"
        rpy="0 0 0" />
      <geometry>
        <mesh
          filename="package://robot_final_urdf/meshes/2_Link.STL" />
      </geometry>
    </collision>
  </link>
  <joint
    name="j_2"
    type="revolute">
    <origin
      xyz="0 0.8 0"
      rpy="3.1416 0 -0.82849" />
    <parent
      link="1_Link" />
    <child
      link="2_Link" />
    <axis
      xyz="0 0 1" />
    <limit
      lower="-3.14"
      upper="3.14"
      effort="0"
      velocity="0" />
  </joint>
  <link
    name="3_Link">
    <inertial>
      <origin
        xyz="-0.000159508971368183 0.387449485560608 -1.04360964314765E-14"
        rpy="0 0 0" />
      <mass
        value="61.548118318606" />
      <inertia
        ixx="4.42913140242951"
        ixy="0.0023321467219595"
        ixz="-4.06213934434842E-15"
        iyy="1.07920117913916"
        iyz="1.78977438402819E-14"
        izz="3.76274315554468" />
    </inertial>
    <visual>
      <origin
        xyz="0 0 0"
        rpy="0 0 0" />
      <geometry>
        <mesh
          filename="package://robot_final_urdf/meshes/3_Link.STL" />
      </geometry>
      <material
        name="">
        <color
          rgba="0.627450980392157 0.627450980392157 0.627450980392157 1" />
      </material>
    </visual>
    <collision>
      <origin
        xyz="0 0 0"
        rpy="0 0 0" />
      <geometry>
        <mesh
          filename="package://robot_final_urdf/meshes/3_Link.STL" />
      </geometry>
    </collision>
  </link>
  <joint
    name="j_3"
    type="revolute">
    <origin
      xyz="0 -0.79 0"
      rpy="-3.1416 0 0.99429" />
    <parent
      link="2_Link" />
    <child
      link="3_Link" />
    <axis
      xyz="0 0 1" />
    <limit
      lower="-3.14"
      upper="3.14"
      effort="0"
      velocity="0" />
  </joint>
  <link
    name="End_effector">
    <inertial>
      <origin
        xyz="-8.88178419700125E-16 6.66133814775094E-16 -0.104160179030907"
        rpy="0 0 0" />
      <mass
        value="1.98877718256192" />
      <inertia
        ixx="0.014221792642956"
        ixy="1.11130722679764E-18"
        ixz="8.53267109746092E-17"
        iyy="0.014221792642956"
        iyz="-7.7412035115465E-17"
        izz="0.0249563063006771" />
    </inertial>
    <visual>
      <origin
        xyz="0 0 0"
        rpy="0 0 0" />
      <geometry>
        <mesh
          filename="package://robot_final_urdf/meshes/End_effector.STL" />
      </geometry>
      <material
        name="">
        <color
          rgba="0.627450980392157 0.627450980392157 0.627450980392157 1" />
      </material>
    </visual>
    <collision>
      <origin
        xyz="0 0 0"
        rpy="0 0 0" />
      <geometry>
        <mesh
          filename="package://robot_final_urdf/meshes/End_effector.STL" />
      </geometry>
    </collision>
  </link>
  <joint
    name="j_4"
    type="fixed">
    <origin
      xyz="0 0.625 0"
      rpy="1.5708 -1.1094 -1.5708" />
    <parent
      link="3_Link" />
    <child
      link="End_effector" />
    <axis
      xyz="0 0 1" />
    <limit
      lower="-3.14"
      upper="3.14"
      effort="0"
      velocity="0" />
  </joint>
</robot>